<sdf version="1.4">
  <model name="track_creator">
    <link name="base_link">
      <self_collide>0</self_collide>
      <pose>0 0 0.28 0 0 0</pose>
      <collision name="base_link_collision">
        <geometry>
          <box>
            <size>1.12 0.68 0.28</size>
          </box>
        </geometry>
      </collision>
      <visual name="base_link_visual">
        <geometry>
          <box>
            <size>1.12 0.68 0.28</size>
          </box>
        </geometry>
      </visual>
    </link>
    <link name="drum1">
      <self_collide>1</self_collide>
      <pose>0.56 0.44 0.142 1.57079632679 0 0</pose>
      <collision name="drum1_collision">
        <geometry>
          <cylinder>
            <radius>0.14</radius>
            <length>0.2</length>
          </cylinder>
        </geometry>
      </collision>
      <visual name="drum1_visual">
        <geometry>
          <cylinder>
            <radius>0.14</radius>
            <length>0.2</length>
          </cylinder>
        </geometry>
      </visual>
    </link>
    <joint name="drum_joint1" type="revolute">
      <pose>0 0 0 0 0 0</pose>
      <parent>base_link</parent>
      <child>drum1</child>
      <axis>
        <xyz>0 1 0</xyz>
      </axis>
    </joint>
    <link name="drum2">
      <self_collide>1</self_collide>
      <pose>0.56 -0.44 0.142 1.57079632679 0 0</pose>
      <collision name="drum2_collision">
        <geometry>
          <cylinder>
            <radius>0.14</radius>
            <length>0.2</length>
          </cylinder>
        </geometry>
      </collision>
      <visual name="drum2_visual">
        <geometry>
          <cylinder>
            <radius>0.14</radius>
            <length>0.2</length>
          </cylinder>
        </geometry>
      </visual>
    </link>
    <joint name="drum_joint2" type="revolute">
      <pose>0 0 0 0 0 0</pose>
      <parent>base_link</parent>
      <child>drum2</child>
      <axis>
        <xyz>0 1 0</xyz>
      </axis>
    </joint>
    <link name="drum3">
      <self_collide>1</self_collide>
      <pose>-0.56 0.44 0.142 1.57079632679 0 0</pose>
      <collision name="drum3_collision">
        <geometry>
          <cylinder>
            <radius>0.14</radius>
            <length>0.2</length>
          </cylinder>
        </geometry>
      </collision>
      <visual name="drum3_visual">
        <geometry>
          <cylinder>
            <radius>0.14</radius>
            <length>0.2</length>
          </cylinder>
        </geometry>
      </visual>
    </link>
    <joint name="drum_joint3" type="revolute">
      <pose>0 0 0 0 0 0</pose>
      <parent>base_link</parent>
      <child>drum3</child>
      <axis>
        <xyz>0 1 0</xyz>
      </axis>
    </joint>
    <link name="drum4">
      <self_collide>1</self_collide>
      <pose>-0.56 -0.44 0.142 1.57079632679 0 0</pose>
      <collision name="drum4_collision">
        <geometry>
          <cylinder>
            <radius>0.14</radius>
            <length>0.2</length>
          </cylinder>
        </geometry>
      </collision>
      <visual name="drum4_visual">
        <geometry>
          <cylinder>
            <radius>0.14</radius>
            <length>0.2</length>
          </cylinder>
        </geometry>
      </visual>
    </link>
    <joint name="drum_joint4" type="revolute">
      <pose>0 0 0 0 0 0</pose>
      <parent>base_link</parent>
      <child>drum4</child>
      <axis>
        <xyz>0 1 0</xyz>
      </axis>
    </joint>
    <link name="right_pad1">
      <self_collide>1</self_collide>
      <pose>0.459653108251 0.44 0.385626993558 0 -1.39353393257 0</pose>
      <collision name="right_pad1_collision">
        <geometry>
          <box>
            <size>0.6252 0.2 0.002</size>
          </box>
        </geometry>
      </collision>
      <visual name="right_pad1_visual">
        <geometry>
          <box>
            <size>0.6252 0.2 0.002</size>
          </box>
        </geometry>
      </visual>
    </link>
    <joint name="right_pad_joint1" type="revolute">
      <pose>-0.39075 0 0 0 0 0</pose>
      <parent>right_pad1</parent>
      <child>right_pad2</child>
      <axis>
        <xyz>0 1 0</xyz>
      </axis>
    </joint>
    <link name="right_pad2">
      <self_collide>1</self_collide>
      <pose>0.162106348692 0.44 0.905900796448 0 -2.78706786513 0</pose>
      <collision name="right_pad2_collision">
        <geometry>
          <box>
            <size>0.6252 0.2 0.002</size>
          </box>
        </geometry>
      </collision>
      <visual name="right_pad2_visual">
        <geometry>
          <box>
            <size>0.6252 0.2 0.002</size>
          </box>
        </geometry>
      </visual>
    </link>
    <joint name="right_pad_joint2" type="revolute">
      <pose>-0.39075 0 0 0 0 0</pose>
      <parent>right_pad2</parent>
      <child>right_pad3</child>
      <axis>
        <xyz>0 1 0</xyz>
      </axis>
    </joint>
    <link name="right_pad3">
      <self_collide>1</self_collide>
      <pose>-0.595093519118 0.44 1.04154760578 0 3.14159265359 0</pose>
      <collision name="right_pad3_collision">
        <geometry>
          <box>
            <size>0.6252 0.2 0.002</size>
          </box>
        </geometry>
      </collision>
      <visual name="right_pad3_visual">
        <geometry>
          <box>
            <size>0.6252 0.2 0.002</size>
          </box>
        </geometry>
      </visual>
    </link>
    <joint name="right_pad_joint3" type="revolute">
      <pose>-0.39075 0 0 0 0 0</pose>
      <parent>right_pad3</parent>
      <child>right_pad4</child>
      <axis>
        <xyz>0 1 0</xyz>
      </axis>
    </joint>
    <link name="right_pad4">
      <self_collide>1</self_collide>
      <pose>-1.05474662737 0.44 0.656920612223 0 1.74805872102 0</pose>
      <collision name="right_pad4_collision">
        <geometry>
          <box>
            <size>0.6252 0.2 0.002</size>
          </box>
        </geometry>
      </collision>
      <visual name="right_pad4_visual">
        <geometry>
          <box>
            <size>0.6252 0.2 0.002</size>
          </box>
        </geometry>
      </visual>
    </link>
    <joint name="right_pad_joint4" type="revolute">
      <pose>-0.39075 0 0 0 0 0</pose>
      <parent>right_pad4</parent>
      <child>right_pad5</child>
      <axis>
        <xyz>0 1 0</xyz>
      </axis>
    </joint>
    <link name="right_pad5">
      <self_collide>1</self_collide>
      <pose>-0.75719986781 0.44 0.136646809333 0 0.35452478846 0</pose>
      <collision name="right_pad5_collision">
        <geometry>
          <box>
            <size>0.6252 0.2 0.002</size>
          </box>
        </geometry>
      </collision>
      <visual name="right_pad5_visual">
        <geometry>
          <box>
            <size>0.6252 0.2 0.002</size>
          </box>
        </geometry>
      </visual>
    </link>
    <joint name="right_pad_joint5" type="revolute">
      <pose>-0.39075 0 0 0 0 0</pose>
      <parent>right_pad5</parent>
      <child>right_pad1</child>
      <axis>
        <xyz>0 1 0</xyz>
      </axis>
    </joint>
    <link name="left_pad1">
      <self_collide>1</self_collide>
      <pose>0.459653108251 -0.44 0.385626993558 0 -1.39353393257 0</pose>
      <collision name="left_pad1_collision">
        <geometry>
          <box>
            <size>0.6252 0.2 0.002</size>
          </box>
        </geometry>
      </collision>
      <visual name="left_pad1_visual">
        <geometry>
          <box>
            <size>0.6252 0.2 0.002</size>
          </box>
        </geometry>
      </visual>
    </link>
    <joint name="left_pad_joint1" type="revolute">
      <pose>-0.39075 0 0 0 0 0</pose>
      <parent>left_pad1</parent>
      <child>left_pad2</child>
      <axis>
        <xyz>0 1 0</xyz>
      </axis>
    </joint>
    <link name="left_pad2">
      <self_collide>1</self_collide>
      <pose>0.162106348692 -0.44 0.905900796448 0 -2.78706786513 0</pose>
      <collision name="left_pad2_collision">
        <geometry>
          <box>
            <size>0.6252 0.2 0.002</size>
          </box>
        </geometry>
      </collision>
      <visual name="left_pad2_visual">
        <geometry>
          <box>
            <size>0.6252 0.2 0.002</size>
          </box>
        </geometry>
      </visual>
    </link>
    <joint name="left_pad_joint2" type="revolute">
      <pose>-0.39075 0 0 0 0 0</pose>
      <parent>left_pad2</parent>
      <child>left_pad3</child>
      <axis>
        <xyz>0 1 0</xyz>
      </axis>
    </joint>
    <link name="left_pad3">
      <self_collide>1</self_collide>
      <pose>-0.595093519118 -0.44 1.04154760578 0 3.14159265359 0</pose>
      <collision name="left_pad3_collision">
        <geometry>
          <box>
            <size>0.6252 0.2 0.002</size>
          </box>
        </geometry>
      </collision>
      <visual name="left_pad3_visual">
        <geometry>
          <box>
            <size>0.6252 0.2 0.002</size>
          </box>
        </geometry>
      </visual>
    </link>
    <joint name="left_pad_joint3" type="revolute">
      <pose>-0.39075 0 0 0 0 0</pose>
      <parent>left_pad3</parent>
      <child>left_pad4</child>
      <axis>
        <xyz>0 1 0</xyz>
      </axis>
    </joint>
    <link name="left_pad4">
      <self_collide>1</self_collide>
      <pose>-1.05474662737 -0.44 0.656920612223 0 1.74805872102 0</pose>
      <collision name="left_pad4_collision">
        <geometry>
          <box>
            <size>0.6252 0.2 0.002</size>
          </box>
        </geometry>
      </collision>
      <visual name="left_pad4_visual">
        <geometry>
          <box>
            <size>0.6252 0.2 0.002</size>
          </box>
        </geometry>
      </visual>
    </link>
    <joint name="left_pad_joint4" type="revolute">
      <pose>-0.39075 0 0 0 0 0</pose>
      <parent>left_pad4</parent>
      <child>left_pad5</child>
      <axis>
        <xyz>0 1 0</xyz>
      </axis>
    </joint>
    <link name="left_pad5">
      <self_collide>1</self_collide>
      <pose>-0.75719986781 -0.44 0.136646809333 0 0.35452478846 0</pose>
      <collision name="left_pad5_collision">
        <geometry>
          <box>
            <size>0.6252 0.2 0.002</size>
          </box>
        </geometry>
      </collision>
      <visual name="left_pad5_visual">
        <geometry>
          <box>
            <size>0.6252 0.2 0.002</size>
          </box>
        </geometry>
      </visual>
    </link>
    <joint name="left_pad_joint5" type="revolute">
      <pose>-0.39075 0 0 0 0 0</pose>
      <parent>left_pad5</parent>
      <child>left_pad1</child>
      <axis>
        <xyz>0 1 0</xyz>
      </axis>
    </joint>
  </model>
</sdf>
